Workbook

Sheet Dashboard
B2: Cookbook Dashboard
B4: All Months
C5: New People | D5: Intro Asks | E5: Floor Walks | F5: Quote F-Ups | G5: Seed Touches
B6: Total: | C6: =C21 -> 0 | D6: =D21 -> 0 | E6: =E21 -> 0 | F6: =F21 -> 0 | G6: =G21 -> 0
B8: Perfect Weeks (5 of 5)
B9: =SUM(I16:I20) -> 0
B11: % of Committed Behaviors
B12: =J21 -> 0
B14: By Month
B15: Month | C15: New People | D15: Intro Asks | E15: Floor Walks | F15: Quote F-Ups | G15: Seed Touches | H15: Weeks | I15: Perfect Wks | J15: % of Committed
B16: August | C16: =Aug!M6 -> 0 | D16: =Aug!M7 -> 0 | E16: =Aug!M8 -> 0 | F16: =Aug!M9 -> 0 | G16: =Aug!M10 -> 0 | H16: =COUNTIF(Aug!$B$1:$B$500, "Total:") -> 2 | I16: =Aug!L13 -> 0 | J16: =IFERROR(SUM(C16:G16)/(SUMIF(Aug!$B$1:$B$500, "Weekly Goals:", Aug!$C$1:$C$500)+SUMIF(Aug!$B$1:$B$500, "Weekly Goals:", Aug!$D$1:$D$500)+SUMIF(Aug!$B$1:$B$500, "Weekly Goals:", Aug!$E$1:$E$500)+SUMIF(Aug!$B$1:$B$500, "Weekly Goals:", Aug!$F$1:$F$500)+SUMIF(Aug!$B$1:$B$500, "Weekly Goals:", Aug!$G$1:$G$500)), 0) -> 0
B17: September | C17: =Sept!M6 -> 0 | D17: =Sept!M7 -> 0 | E17: =Sept!M8 -> 0 | F17: =Sept!M9 -> 0 | G17: =Sept!M10 -> 0 | H17: =COUNTIF(Sept!$B$1:$B$500, "Total:") -> 5 | I17: =Sept!L13 -> 0 | J17: =IFERROR(SUM(C17:G17)/(SUMIF(Sept!$B$1:$B$500, "Weekly Goals:", Sept!$C$1:$C$500)+SUMIF(Sept!$B$1:$B$500, "Weekly Goals:", Sept!$D$1:$D$500)+SUMIF(Sept!$B$1:$B$500, "Weekly Goals:", Sept!$E$1:$E$500)+SUMIF(Sept!$B$1:$B$500, "Weekly Goals:", Sept!$F$1:$F$500)+SUMIF(Sept!$B$1:$B$500, "Weekly Goals:", Sept!$G$1:$G$500)), 0) -> 0
B18: October | C18: =Oct!M6 -> 0 | D18: =Oct!M7 -> 0 | E18: =Oct!M8 -> 0 | F18: =Oct!M9 -> 0 | G18: =Oct!M10 -> 0 | H18: =COUNTIF(Oct!$B$1:$B$500, "Total:") -> 4 | I18: =Oct!L13 -> 0 | J18: =IFERROR(SUM(C18:G18)/(SUMIF(Oct!$B$1:$B$500, "Weekly Goals:", Oct!$C$1:$C$500)+SUMIF(Oct!$B$1:$B$500, "Weekly Goals:", Oct!$D$1:$D$500)+SUMIF(Oct!$B$1:$B$500, "Weekly Goals:", Oct!$E$1:$E$500)+SUMIF(Oct!$B$1:$B$500, "Weekly Goals:", Oct!$F$1:$F$500)+SUMIF(Oct!$B$1:$B$500, "Weekly Goals:", Oct!$G$1:$G$500)), 0) -> 0
B19: November | C19: =Nov!M6 -> 0 | D19: =Nov!M7 -> 0 | E19: =Nov!M8 -> 0 | F19: =Nov!M9 -> 0 | G19: =Nov!M10 -> 0 | H19: =COUNTIF(Nov!$B$1:$B$500, "Total:") -> 4 | I19: =Nov!L13 -> 0 | J19: =IFERROR(SUM(C19:G19)/(SUMIF(Nov!$B$1:$B$500, "Weekly Goals:", Nov!$C$1:$C$500)+SUMIF(Nov!$B$1:$B$500, "Weekly Goals:", Nov!$D$1:$D$500)+SUMIF(Nov!$B$1:$B$500, "Weekly Goals:", Nov!$E$1:$E$500)+SUMIF(Nov!$B$1:$B$500, "Weekly Goals:", Nov!$F$1:$F$500)+SUMIF(Nov!$B$1:$B$500, "Weekly Goals:", Nov!$G$1:$G$500)), 0) -> 0
B20: December | C20: =Dec!M6 -> 0 | D20: =Dec!M7 -> 0 | E20: =Dec!M8 -> 0 | F20: =Dec!M9 -> 0 | G20: =Dec!M10 -> 0 | H20: =COUNTIF(Dec!$B$1:$B$500, "Total:") -> 5 | I20: =Dec!L13 -> 0 | J20: =IFERROR(SUM(C20:G20)/(SUMIF(Dec!$B$1:$B$500, "Weekly Goals:", Dec!$C$1:$C$500)+SUMIF(Dec!$B$1:$B$500, "Weekly Goals:", Dec!$D$1:$D$500)+SUMIF(Dec!$B$1:$B$500, "Weekly Goals:", Dec!$E$1:$E$500)+SUMIF(Dec!$B$1:$B$500, "Weekly Goals:", Dec!$F$1:$F$500)+SUMIF(Dec!$B$1:$B$500, "Weekly Goals:", Dec!$G$1:$G$500)), 0) -> 0
B21: Total: | C21: =SUM(C16:C20) -> 0 | D21: =SUM(D16:D20) -> 0 | E21: =SUM(E16:E20) -> 0 | F21: =SUM(F16:F20) -> 0 | G21: =SUM(G16:G20) -> 0 | H21: =SUM(H16:H20) -> 20 | I21: =SUM(I16:I20) -> 0 | J21: =IFERROR(SUM(C21:G21)/(SUMIF(Aug!$B$1:$B$500, "Weekly Goals:", Aug!$C$1:$C$500)+SUMIF(Aug!$B$1:$B$500, "Weekly Goals:", Aug!$D$1:$D$500)+SUMIF(Aug!$B$1:$B$500, "Weekly Goals:", Aug!$E$1:$E$500)+SUMIF(Aug!$B$1:$B$500, "Weekly Goals:", Aug!$F$1:$F$500)+SUMIF(Aug!$B$1:$B$500, "Weekly Goals:", Aug!$G$1:$G$500)+SUMIF(Sept!$B$1:$B$500, "Weekly Goals:", Sept!$C$1:$C$500)+SUMIF(Sept!$B$1:$B$500, "Weekly Goals:", Sept!$D$1:$D$500)+SUMIF(Sept!$B$1:$B$500, "Weekly Goals:", Sept!$E$1:$E$500)+SUMIF(Sept!$B$1:$B$500, "Weekly Goals:", Sept!$F$1:$F$500)+SUMIF(Sept!$B$1:$B$500, "Weekly Goals:", Sept!$G$1:$G$500)+SUMIF(Oct!$B$1:$B$500, "Weekly Goals:", Oct!$C$1:$C$500)+SUMIF(Oct!$B$1:$B$500, "Weekly Goals:", Oct!$D$1:$D$500)+SUMIF(Oct!$B$1:$B$500, "Weekly Goals:", Oct!$E$1:$E$500)+SUMIF(Oct!$B$1:$B$500, "Weekly Goals:", Oct!$F$1:$F$500)+SUMIF(Oct!$B$1:$B$500, "Weekly Goals:", Oct!$G$1:$G$500)+SUMIF(Nov!$B$1:$B$500, "Weekly Goals:", Nov!$C$1:$C$500)+SUMIF(Nov!$B$1:$B$500, "Weekly Goals:", Nov!$D$1:$D$500)+SUMIF(Nov!$B$1:$B$500, "Weekly Goals:", Nov!$E$1:$E$500)+SUMIF(Nov!$B$1:$B$500, "Weekly Goals:", Nov!$F$1:$F$500)+SUMIF(Nov!$B$1:$B$500, "Weekly Goals:", Nov!$G$1:$G$500)+SUMIF(Dec!$B$1:$B$500, "Weekly Goals:", Dec!$C$1:$C$500)+SUMIF(Dec!$B$1:$B$500, "Weekly Goals:", Dec!$D$1:$D$500)+SUMIF(Dec!$B$1:$B$500, "Weekly Goals:", Dec!$E$1:$E$500)+SUMIF(Dec!$B$1:$B$500, "Weekly Goals:", Dec!$F$1:$F$500)+SUMIF(Dec!$B$1:$B$500, "Weekly Goals:", Dec!$G$1:$G$500)), 0) -> 0
B23: What Counts
B24: New People: a real conversation with someone new inside a GROW account - name captured.
B25: Intro Asks: a sister-site or referral ask made to a champion. Asked is what counts, not answered.
B26: Floor Walks: walked part of a site and left a punch list behind.
B27: Quote F-Ups: touched a stalled quote - call, email, or in person.
B28: Seed Touches: a SEED-list touch carrying a reference story or referral. Cold doesn't count.
B30: Notes
B31: Weekly goals sit in the yellow cells on each month tab - change them week by week with Dan.
B32: Every block is a full Mon-Fri week. A week crossing two months sits whole in the month holding its Wednesday.

Sheet Aug
B2: 46235
B4: Weekly Goals: | C4: 3 | D4: 1 | E4: 1 | F4: 5 | G4: 2
B5: To Go: | C5: =IF(C4="", "", C4-SUM(C7:C11)) -> 3 | D5: =IF(D4="", "", D4-SUM(D7:D11)) -> 1 | E5: =IF(E4="", "", E4-SUM(E7:E11)) -> 1 | F5: =IF(F4="", "", F4-SUM(F7:F11)) -> 5 | G5: =IF(G4="", "", G4-SUM(G7:G11)) -> 2 | L5: August Totals
C6: New People | D6: Intro Asks | E6: Floor Walks | F6: Quote F-Ups | G6: Seed Touches | I6: Aug 17 - 21 | L6: New People | M6: =SUM(J7,J19) -> 0
B7: 46251 | I7: New People | J7: =IFERROR(IF(C13=0, "", C13), "") | L7: Intro Asks | M7: =SUM(J8,J20) -> 0
B8: =B7+1 -> 46252 | I8: Intro Asks | J8: =IFERROR(IF(D13=0, "", D13), "") | L8: Floor Walks | M8: =SUM(J9,J21) -> 0
B9: =B8+1 -> 46253 | I9: Floor Walks | J9: =IFERROR(IF(E13=0, "", E13), "") | L9: Quote F-Ups | M9: =SUM(J10,J22) -> 0
B10: =B9+1 -> 46254 | I10: Quote F-Ups | J10: =IFERROR(IF(F13=0, "", F13), "") | L10: Seed Touches | M10: =SUM(J11,J23) -> 0
B11: =B10+1 -> 46255 | I11: Seed Touches | J11: =IFERROR(IF(G13=0, "", G13), "")
I12: Goals Hit (of 5) | J12: =IF(COUNT(C4:G4)=0, "", (SUM(C7:C11)>=C4)+(SUM(D7:D11)>=D4)+(SUM(E7:E11)>=E4)+(SUM(F7:F11)>=F4)+(SUM(G7:G11)>=G4)) -> 0 | L12: Perfect Weeks (5 of 5)
B13: Total: | C13: =IFERROR(IF(SUM(C7:C11)=0, "", SUM(C7:C11)), "") | D13: =IFERROR(IF(SUM(D7:D11)=0, "", SUM(D7:D11)), "") | E13: =IFERROR(IF(SUM(E7:E11)=0, "", SUM(E7:E11)), "") | F13: =IFERROR(IF(SUM(F7:F11)=0, "", SUM(F7:F11)), "") | G13: =IFERROR(IF(SUM(G7:G11)=0, "", SUM(G7:G11)), "") | L13: =(J12=5)+(J24=5) -> 0
B16: Weekly Goals: | C16: 3 | D16: 1 | E16: 1 | F16: 5 | G16: 2
B17: To Go: | C17: =IF(C16="", "", C16-SUM(C19:C23)) -> 3 | D17: =IF(D16="", "", D16-SUM(D19:D23)) -> 1 | E17: =IF(E16="", "", E16-SUM(E19:E23)) -> 1 | F17: =IF(F16="", "", F16-SUM(F19:F23)) -> 5 | G17: =IF(G16="", "", G16-SUM(G19:G23)) -> 2
C18: New People | D18: Intro Asks | E18: Floor Walks | F18: Quote F-Ups | G18: Seed Touches | I18: Aug 24 - 28
B19: 46258 | I19: New People | J19: =IFERROR(IF(C25=0, "", C25), "")
B20: =B19+1 -> 46259 | I20: Intro Asks | J20: =IFERROR(IF(D25=0, "", D25), "")
B21: =B20+1 -> 46260 | I21: Floor Walks | J21: =IFERROR(IF(E25=0, "", E25), "")
B22: =B21+1 -> 46261 | I22: Quote F-Ups | J22: =IFERROR(IF(F25=0, "", F25), "")
B23: =B22+1 -> 46262 | I23: Seed Touches | J23: =IFERROR(IF(G25=0, "", G25), "")
I24: Goals Hit (of 5) | J24: =IF(COUNT(C16:G16)=0, "", (SUM(C19:C23)>=C16)+(SUM(D19:D23)>=D16)+(SUM(E19:E23)>=E16)+(SUM(F19:F23)>=F16)+(SUM(G19:G23)>=G16)) -> 0
B25: Total: | C25: =IFERROR(IF(SUM(C19:C23)=0, "", SUM(C19:C23)), "") | D25: =IFERROR(IF(SUM(D19:D23)=0, "", SUM(D19:D23)), "") | E25: =IFERROR(IF(SUM(E19:E23)=0, "", SUM(E19:E23)), "") | F25: =IFERROR(IF(SUM(F19:F23)=0, "", SUM(F19:F23)), "") | G25: =IFERROR(IF(SUM(G19:G23)=0, "", SUM(G19:G23)), "")

Sheet Sept
B2: 46266
B4: Weekly Goals: | C4: 3 | D4: 1 | E4: 1 | F4: 5 | G4: 2
B5: To Go: | C5: =IF(C4="", "", C4-SUM(C7:C11)) -> 3 | D5: =IF(D4="", "", D4-SUM(D7:D11)) -> 1 | E5: =IF(E4="", "", E4-SUM(E7:E11)) -> 1 | F5: =IF(F4="", "", F4-SUM(F7:F11)) -> 5 | G5: =IF(G4="", "", G4-SUM(G7:G11)) -> 2 | L5: September Totals
C6: New People | D6: Intro Asks | E6: Floor Walks | F6: Quote F-Ups | G6: Seed Touches | I6: Aug 31 - Sep 4 | L6: New People | M6: =SUM(J7,J19,J31,J43,J55) -> 0
B7: 46265 | I7: New People | J7: =IFERROR(IF(C13=0, "", C13), "") | L7: Intro Asks | M7: =SUM(J8,J20,J32,J44,J56) -> 0
B8: =B7+1 -> 46266 | I8: Intro Asks | J8: =IFERROR(IF(D13=0, "", D13), "") | L8: Floor Walks | M8: =SUM(J9,J21,J33,J45,J57) -> 0
B9: =B8+1 -> 46267 | I9: Floor Walks | J9: =IFERROR(IF(E13=0, "", E13), "") | L9: Quote F-Ups | M9: =SUM(J10,J22,J34,J46,J58) -> 0
B10: =B9+1 -> 46268 | I10: Quote F-Ups | J10: =IFERROR(IF(F13=0, "", F13), "") | L10: Seed Touches | M10: =SUM(J11,J23,J35,J47,J59) -> 0
B11: =B10+1 -> 46269 | I11: Seed Touches | J11: =IFERROR(IF(G13=0, "", G13), "")
I12: Goals Hit (of 5) | J12: =IF(COUNT(C4:G4)=0, "", (SUM(C7:C11)>=C4)+(SUM(D7:D11)>=D4)+(SUM(E7:E11)>=E4)+(SUM(F7:F11)>=F4)+(SUM(G7:G11)>=G4)) -> 0 | L12: Perfect Weeks (5 of 5)
B13: Total: | C13: =IFERROR(IF(SUM(C7:C11)=0, "", SUM(C7:C11)), "") | D13: =IFERROR(IF(SUM(D7:D11)=0, "", SUM(D7:D11)), "") | E13: =IFERROR(IF(SUM(E7:E11)=0, "", SUM(E7:E11)), "") | F13: =IFERROR(IF(SUM(F7:F11)=0, "", SUM(F7:F11)), "") | G13: =IFERROR(IF(SUM(G7:G11)=0, "", SUM(G7:G11)), "") | L13: =(J12=5)+(J24=5)+(J36=5)+(J48=5)+(J60=5) -> 0
B16: Weekly Goals: | C16: 3 | D16: 1 | E16: 1 | F16: 5 | G16: 2
B17: To Go: | C17: =IF(C16="", "", C16-SUM(C19:C23)) -> 3 | D17: =IF(D16="", "", D16-SUM(D19:D23)) -> 1 | E17: =IF(E16="", "", E16-SUM(E19:E23)) -> 1 | F17: =IF(F16="", "", F16-SUM(F19:F23)) -> 5 | G17: =IF(G16="", "", G16-SUM(G19:G23)) -> 2
C18: New People | D18: Intro Asks | E18: Floor Walks | F18: Quote F-Ups | G18: Seed Touches | I18: Sep 7 - 11
B19: 46272 | I19: New People | J19: =IFERROR(IF(C25=0, "", C25), "")
B20: =B19+1 -> 46273 | I20: Intro Asks | J20: =IFERROR(IF(D25=0, "", D25), "")
B21: =B20+1 -> 46274 | I21: Floor Walks | J21: =IFERROR(IF(E25=0, "", E25), "")
B22: =B21+1 -> 46275 | I22: Quote F-Ups | J22: =IFERROR(IF(F25=0, "", F25), "")
B23: =B22+1 -> 46276 | I23: Seed Touches | J23: =IFERROR(IF(G25=0, "", G25), "")
I24: Goals Hit (of 5) | J24: =IF(COUNT(C16:G16)=0, "", (SUM(C19:C23)>=C16)+(SUM(D19:D23)>=D16)+(SUM(E19:E23)>=E16)+(SUM(F19:F23)>=F16)+(SUM(G19:G23)>=G16)) -> 0
B25: Total: | C25: =IFERROR(IF(SUM(C19:C23)=0, "", SUM(C19:C23)), "") | D25: =IFERROR(IF(SUM(D19:D23)=0, "", SUM(D19:D23)), "") | E25: =IFERROR(IF(SUM(E19:E23)=0, "", SUM(E19:E23)), "") | F25: =IFERROR(IF(SUM(F19:F23)=0, "", SUM(F19:F23)), "") | G25: =IFERROR(IF(SUM(G19:G23)=0, "", SUM(G19:G23)), "")
B28: Weekly Goals: | C28: 3 | D28: 1 | E28: 1 | F28: 5 | G28: 2
B29: To Go: | C29: =IF(C28="", "", C28-SUM(C31:C35)) -> 3 | D29: =IF(D28="", "", D28-SUM(D31:D35)) -> 1 | E29: =IF(E28="", "", E28-SUM(E31:E35)) -> 1 | F29: =IF(F28="", "", F28-SUM(F31:F35)) -> 5 | G29: =IF(G28="", "", G28-SUM(G31:G35)) -> 2
C30: New People | D30: Intro Asks | E30: Floor Walks | F30: Quote F-Ups | G30: Seed Touches | I30: Sep 14 - 18
B31: 46279 | I31: New People | J31: =IFERROR(IF(C37=0, "", C37), "")
B32: =B31+1 -> 46280 | I32: Intro Asks | J32: =IFERROR(IF(D37=0, "", D37), "")
B33: =B32+1 -> 46281 | I33: Floor Walks | J33: =IFERROR(IF(E37=0, "", E37), "")
B34: =B33+1 -> 46282 | I34: Quote F-Ups | J34: =IFERROR(IF(F37=0, "", F37), "")
B35: =B34+1 -> 46283 | I35: Seed Touches | J35: =IFERROR(IF(G37=0, "", G37), "")
I36: Goals Hit (of 5) | J36: =IF(COUNT(C28:G28)=0, "", (SUM(C31:C35)>=C28)+(SUM(D31:D35)>=D28)+(SUM(E31:E35)>=E28)+(SUM(F31:F35)>=F28)+(SUM(G31:G35)>=G28)) -> 0
B37: Total: | C37: =IFERROR(IF(SUM(C31:C35)=0, "", SUM(C31:C35)), "") | D37: =IFERROR(IF(SUM(D31:D35)=0, "", SUM(D31:D35)), "") | E37: =IFERROR(IF(SUM(E31:E35)=0, "", SUM(E31:E35)), "") | F37: =IFERROR(IF(SUM(F31:F35)=0, "", SUM(F31:F35)), "") | G37: =IFERROR(IF(SUM(G31:G35)=0, "", SUM(G31:G35)), "")
B40: Weekly Goals: | C40: 3 | D40: 1 | E40: 1 | F40: 5 | G40: 2
B41: To Go: | C41: =IF(C40="", "", C40-SUM(C43:C47)) -> 3 | D41: =IF(D40="", "", D40-SUM(D43:D47)) -> 1 | E41: =IF(E40="", "", E40-SUM(E43:E47)) -> 1 | F41: =IF(F40="", "", F40-SUM(F43:F47)) -> 5 | G41: =IF(G40="", "", G40-SUM(G43:G47)) -> 2
C42: New People | D42: Intro Asks | E42: Floor Walks | F42: Quote F-Ups | G42: Seed Touches | I42: Sep 21 - 25
B43: 46286 | I43: New People | J43: =IFERROR(IF(C49=0, "", C49), "")
B44: =B43+1 -> 46287 | I44: Intro Asks | J44: =IFERROR(IF(D49=0, "", D49), "")
B45: =B44+1 -> 46288 | I45: Floor Walks | J45: =IFERROR(IF(E49=0, "", E49), "")
B46: =B45+1 -> 46289 | I46: Quote F-Ups | J46: =IFERROR(IF(F49=0, "", F49), "")
B47: =B46+1 -> 46290 | I47: Seed Touches | J47: =IFERROR(IF(G49=0, "", G49), "")
I48: Goals Hit (of 5) | J48: =IF(COUNT(C40:G40)=0, "", (SUM(C43:C47)>=C40)+(SUM(D43:D47)>=D40)+(SUM(E43:E47)>=E40)+(SUM(F43:F47)>=F40)+(SUM(G43:G47)>=G40)) -> 0
...

Sheet Oct
B2: 46296
B4: Weekly Goals: | C4: 3 | D4: 1 | E4: 1 | F4: 5 | G4: 2
B5: To Go: | C5: =IF(C4="", "", C4-SUM(C7:C11)) -> 3 | D5: =IF(D4="", "", D4-SUM(D7:D11)) -> 1 | E5: =IF(E4="", "", E4-SUM(E7:E11)) -> 1 | F5: =IF(F4="", "", F4-SUM(F7:F11)) -> 5 | G5: =IF(G4="", "", G4-SUM(G7:G11)) -> 2 | L5: October Totals
C6: New People | D6: Intro Asks | E6: Floor Walks | F6: Quote F-Ups | G6: Seed Touches | I6: Oct 5 - 9 | L6: New People | M6: =SUM(J7,J19,J31,J43) -> 0
B7: 46300 | I7: New People | J7: =IFERROR(IF(C13=0, "", C13), "") | L7: Intro Asks | M7: =SUM(J8,J20,J32,J44) -> 0
B8: =B7+1 -> 46301 | I8: Intro Asks | J8: =IFERROR(IF(D13=0, "", D13), "") | L8: Floor Walks | M8: =SUM(J9,J21,J33,J45) -> 0
B9: =B8+1 -> 46302 | I9: Floor Walks | J9: =IFERROR(IF(E13=0, "", E13), "") | L9: Quote F-Ups | M9: =SUM(J10,J22,J34,J46) -> 0
B10: =B9+1 -> 46303 | I10: Quote F-Ups | J10: =IFERROR(IF(F13=0, "", F13), "") | L10: Seed Touches | M10: =SUM(J11,J23,J35,J47) -> 0
B11: =B10+1 -> 46304 | I11: Seed Touches | J11: =IFERROR(IF(G13=0, "", G13), "")
I12: Goals Hit (of 5) | J12: =IF(COUNT(C4:G4)=0, "", (SUM(C7:C11)>=C4)+(SUM(D7:D11)>=D4)+(SUM(E7:E11)>=E4)+(SUM(F7:F11)>=F4)+(SUM(G7:G11)>=G4)) -> 0 | L12: Perfect Weeks (5 of 5)
B13: Total: | C13: =IFERROR(IF(SUM(C7:C11)=0, "", SUM(C7:C11)), "") | D13: =IFERROR(IF(SUM(D7:D11)=0, "", SUM(D7:D11)), "") | E13: =IFERROR(IF(SUM(E7:E11)=0, "", SUM(E7:E11)), "") | F13: =IFERROR(IF(SUM(F7:F11)=0, "", SUM(F7:F11)), "") | G13: =IFERROR(IF(SUM(G7:G11)=0, "", SUM(G7:G11)), "") | L13: =(J12=5)+(J24=5)+(J36=5)+(J48=5) -> 0
B16: Weekly Goals: | C16: 3 | D16: 1 | E16: 1 | F16: 5 | G16: 2
B17: To Go: | C17: =IF(C16="", "", C16-SUM(C19:C23)) -> 3 | D17: =IF(D16="", "", D16-SUM(D19:D23)) -> 1 | E17: =IF(E16="", "", E16-SUM(E19:E23)) -> 1 | F17: =IF(F16="", "", F16-SUM(F19:F23)) -> 5 | G17: =IF(G16="", "", G16-SUM(G19:G23)) -> 2
C18: New People | D18: Intro Asks | E18: Floor Walks | F18: Quote F-Ups | G18: Seed Touches | I18: Oct 12 - 16
B19: 46307 | I19: New People | J19: =IFERROR(IF(C25=0, "", C25), "")
B20: =B19+1 -> 46308 | I20: Intro Asks | J20: =IFERROR(IF(D25=0, "", D25), "")
B21: =B20+1 -> 46309 | I21: Floor Walks | J21: =IFERROR(IF(E25=0, "", E25), "")
B22: =B21+1 -> 46310 | I22: Quote F-Ups | J22: =IFERROR(IF(F25=0, "", F25), "")
B23: =B22+1 -> 46311 | I23: Seed Touches | J23: =IFERROR(IF(G25=0, "", G25), "")
I24: Goals Hit (of 5) | J24: =IF(COUNT(C16:G16)=0, "", (SUM(C19:C23)>=C16)+(SUM(D19:D23)>=D16)+(SUM(E19:E23)>=E16)+(SUM(F19:F23)>=F16)+(SUM(G19:G23)>=G16)) -> 0
B25: Total: | C25: =IFERROR(IF(SUM(C19:C23)=0, "", SUM(C19:C23)), "") | D25: =IFERROR(IF(SUM(D19:D23)=0, "", SUM(D19:D23)), "") | E25: =IFERROR(IF(SUM(E19:E23)=0, "", SUM(E19:E23)), "") | F25: =IFERROR(IF(SUM(F19:F23)=0, "", SUM(F19:F23)), "") | G25: =IFERROR(IF(SUM(G19:G23)=0, "", SUM(G19:G23)), "")
B28: Weekly Goals: | C28: 3 | D28: 1 | E28: 1 | F28: 5 | G28: 2
B29: To Go: | C29: =IF(C28="", "", C28-SUM(C31:C35)) -> 3 | D29: =IF(D28="", "", D28-SUM(D31:D35)) -> 1 | E29: =IF(E28="", "", E28-SUM(E31:E35)) -> 1 | F29: =IF(F28="", "", F28-SUM(F31:F35)) -> 5 | G29: =IF(G28="", "", G28-SUM(G31:G35)) -> 2
C30: New People | D30: Intro Asks | E30: Floor Walks | F30: Quote F-Ups | G30: Seed Touches | I30: Oct 19 - 23
B31: 46314 | I31: New People | J31: =IFERROR(IF(C37=0, "", C37), "")
B32: =B31+1 -> 46315 | I32: Intro Asks | J32: =IFERROR(IF(D37=0, "", D37), "")
B33: =B32+1 -> 46316 | I33: Floor Walks | J33: =IFERROR(IF(E37=0, "", E37), "")
B34: =B33+1 -> 46317 | I34: Quote F-Ups | J34: =IFERROR(IF(F37=0, "", F37), "")
B35: =B34+1 -> 46318 | I35: Seed Touches | J35: =IFERROR(IF(G37=0, "", G37), "")
I36: Goals Hit (of 5) | J36: =IF(COUNT(C28:G28)=0, "", (SUM(C31:C35)>=C28)+(SUM(D31:D35)>=D28)+(SUM(E31:E35)>=E28)+(SUM(F31:F35)>=F28)+(SUM(G31:G35)>=G28)) -> 0
B37: Total: | C37: =IFERROR(IF(SUM(C31:C35)=0, "", SUM(C31:C35)), "") | D37: =IFERROR(IF(SUM(D31:D35)=0, "", SUM(D31:D35)), "") | E37: =IFERROR(IF(SUM(E31:E35)=0, "", SUM(E31:E35)), "") | F37: =IFERROR(IF(SUM(F31:F35)=0, "", SUM(F31:F35)), "") | G37: =IFERROR(IF(SUM(G31:G35)=0, "", SUM(G31:G35)), "")
B40: Weekly Goals: | C40: 3 | D40: 1 | E40: 1 | F40: 5 | G40: 2
B41: To Go: | C41: =IF(C40="", "", C40-SUM(C43:C47)) -> 3 | D41: =IF(D40="", "", D40-SUM(D43:D47)) -> 1 | E41: =IF(E40="", "", E40-SUM(E43:E47)) -> 1 | F41: =IF(F40="", "", F40-SUM(F43:F47)) -> 5 | G41: =IF(G40="", "", G40-SUM(G43:G47)) -> 2
C42: New People | D42: Intro Asks | E42: Floor Walks | F42: Quote F-Ups | G42: Seed Touches | I42: Oct 26 - 30
B43: 46321 | I43: New People | J43: =IFERROR(IF(C49=0, "", C49), "")
B44: =B43+1 -> 46322 | I44: Intro Asks | J44: =IFERROR(IF(D49=0, "", D49), "")
B45: =B44+1 -> 46323 | I45: Floor Walks | J45: =IFERROR(IF(E49=0, "", E49), "")
B46: =B45+1 -> 46324 | I46: Quote F-Ups | J46: =IFERROR(IF(F49=0, "", F49), "")
B47: =B46+1 -> 46325 | I47: Seed Touches | J47: =IFERROR(IF(G49=0, "", G49), "")
I48: Goals Hit (of 5) | J48: =IF(COUNT(C40:G40)=0, "", (SUM(C43:C47)>=C40)+(SUM(D43:D47)>=D40)+(SUM(E43:E47)>=E40)+(SUM(F43:F47)>=F40)+(SUM(G43:G47)>=G40)) -> 0
...

Sheet Nov
B2: 46327
B4: Weekly Goals: | C4: 3 | D4: 1 | E4: 1 | F4: 5 | G4: 2
B5: To Go: | C5: =IF(C4="", "", C4-SUM(C7:C11)) -> 3 | D5: =IF(D4="", "", D4-SUM(D7:D11)) -> 1 | E5: =IF(E4="", "", E4-SUM(E7:E11)) -> 1 | F5: =IF(F4="", "", F4-SUM(F7:F11)) -> 5 | G5: =IF(G4="", "", G4-SUM(G7:G11)) -> 2 | L5: November Totals
C6: New People | D6: Intro Asks | E6: Floor Walks | F6: Quote F-Ups | G6: Seed Touches | I6: Nov 2 - 6 | L6: New People | M6: =SUM(J7,J19,J31,J43) -> 0
B7: 46328 | I7: New People | J7: =IFERROR(IF(C13=0, "", C13), "") | L7: Intro Asks | M7: =SUM(J8,J20,J32,J44) -> 0
B8: =B7+1 -> 46329 | I8: Intro Asks | J8: =IFERROR(IF(D13=0, "", D13), "") | L8: Floor Walks | M8: =SUM(J9,J21,J33,J45) -> 0
B9: =B8+1 -> 46330 | I9: Floor Walks | J9: =IFERROR(IF(E13=0, "", E13), "") | L9: Quote F-Ups | M9: =SUM(J10,J22,J34,J46) -> 0
B10: =B9+1 -> 46331 | I10: Quote F-Ups | J10: =IFERROR(IF(F13=0, "", F13), "") | L10: Seed Touches | M10: =SUM(J11,J23,J35,J47) -> 0
B11: =B10+1 -> 46332 | I11: Seed Touches | J11: =IFERROR(IF(G13=0, "", G13), "")
I12: Goals Hit (of 5) | J12: =IF(COUNT(C4:G4)=0, "", (SUM(C7:C11)>=C4)+(SUM(D7:D11)>=D4)+(SUM(E7:E11)>=E4)+(SUM(F7:F11)>=F4)+(SUM(G7:G11)>=G4)) -> 0 | L12: Perfect Weeks (5 of 5)
B13: Total: | C13: =IFERROR(IF(SUM(C7:C11)=0, "", SUM(C7:C11)), "") | D13: =IFERROR(IF(SUM(D7:D11)=0, "", SUM(D7:D11)), "") | E13: =IFERROR(IF(SUM(E7:E11)=0, "", SUM(E7:E11)), "") | F13: =IFERROR(IF(SUM(F7:F11)=0, "", SUM(F7:F11)), "") | G13: =IFERROR(IF(SUM(G7:G11)=0, "", SUM(G7:G11)), "") | L13: =(J12=5)+(J24=5)+(J36=5)+(J48=5) -> 0
B16: Weekly Goals: | C16: 3 | D16: 1 | E16: 1 | F16: 5 | G16: 2
B17: To Go: | C17: =IF(C16="", "", C16-SUM(C19:C23)) -> 3 | D17: =IF(D16="", "", D16-SUM(D19:D23)) -> 1 | E17: =IF(E16="", "", E16-SUM(E19:E23)) -> 1 | F17: =IF(F16="", "", F16-SUM(F19:F23)) -> 5 | G17: =IF(G16="", "", G16-SUM(G19:G23)) -> 2
C18: New People | D18: Intro Asks | E18: Floor Walks | F18: Quote F-Ups | G18: Seed Touches | I18: Nov 9 - 13
B19: 46335 | I19: New People | J19: =IFERROR(IF(C25=0, "", C25), "")
B20: =B19+1 -> 46336 | I20: Intro Asks | J20: =IFERROR(IF(D25=0, "", D25), "")
B21: =B20+1 -> 46337 | I21: Floor Walks | J21: =IFERROR(IF(E25=0, "", E25), "")
B22: =B21+1 -> 46338 | I22: Quote F-Ups | J22: =IFERROR(IF(F25=0, "", F25), "")
B23: =B22+1 -> 46339 | I23: Seed Touches | J23: =IFERROR(IF(G25=0, "", G25), "")
I24: Goals Hit (of 5) | J24: =IF(COUNT(C16:G16)=0, "", (SUM(C19:C23)>=C16)+(SUM(D19:D23)>=D16)+(SUM(E19:E23)>=E16)+(SUM(F19:F23)>=F16)+(SUM(G19:G23)>=G16)) -> 0
B25: Total: | C25: =IFERROR(IF(SUM(C19:C23)=0, "", SUM(C19:C23)), "") | D25: =IFERROR(IF(SUM(D19:D23)=0, "", SUM(D19:D23)), "") | E25: =IFERROR(IF(SUM(E19:E23)=0, "", SUM(E19:E23)), "") | F25: =IFERROR(IF(SUM(F19:F23)=0, "", SUM(F19:F23)), "") | G25: =IFERROR(IF(SUM(G19:G23)=0, "", SUM(G19:G23)), "")
B28: Weekly Goals: | C28: 3 | D28: 1 | E28: 1 | F28: 5 | G28: 2
B29: To Go: | C29: =IF(C28="", "", C28-SUM(C31:C35)) -> 3 | D29: =IF(D28="", "", D28-SUM(D31:D35)) -> 1 | E29: =IF(E28="", "", E28-SUM(E31:E35)) -> 1 | F29: =IF(F28="", "", F28-SUM(F31:F35)) -> 5 | G29: =IF(G28="", "", G28-SUM(G31:G35)) -> 2
C30: New People | D30: Intro Asks | E30: Floor Walks | F30: Quote F-Ups | G30: Seed Touches | I30: Nov 16 - 20
B31: 46342 | I31: New People | J31: =IFERROR(IF(C37=0, "", C37), "")
B32: =B31+1 -> 46343 | I32: Intro Asks | J32: =IFERROR(IF(D37=0, "", D37), "")
B33: =B32+1 -> 46344 | I33: Floor Walks | J33: =IFERROR(IF(E37=0, "", E37), "")
B34: =B33+1 -> 46345 | I34: Quote F-Ups | J34: =IFERROR(IF(F37=0, "", F37), "")
B35: =B34+1 -> 46346 | I35: Seed Touches | J35: =IFERROR(IF(G37=0, "", G37), "")
I36: Goals Hit (of 5) | J36: =IF(COUNT(C28:G28)=0, "", (SUM(C31:C35)>=C28)+(SUM(D31:D35)>=D28)+(SUM(E31:E35)>=E28)+(SUM(F31:F35)>=F28)+(SUM(G31:G35)>=G28)) -> 0
B37: Total: | C37: =IFERROR(IF(SUM(C31:C35)=0, "", SUM(C31:C35)), "") | D37: =IFERROR(IF(SUM(D31:D35)=0, "", SUM(D31:D35)), "") | E37: =IFERROR(IF(SUM(E31:E35)=0, "", SUM(E31:E35)), "") | F37: =IFERROR(IF(SUM(F31:F35)=0, "", SUM(F31:F35)), "") | G37: =IFERROR(IF(SUM(G31:G35)=0, "", SUM(G31:G35)), "")
B40: Weekly Goals: | C40: 3 | D40: 1 | E40: 1 | F40: 5 | G40: 2
B41: To Go: | C41: =IF(C40="", "", C40-SUM(C43:C47)) -> 3 | D41: =IF(D40="", "", D40-SUM(D43:D47)) -> 1 | E41: =IF(E40="", "", E40-SUM(E43:E47)) -> 1 | F41: =IF(F40="", "", F40-SUM(F43:F47)) -> 5 | G41: =IF(G40="", "", G40-SUM(G43:G47)) -> 2
C42: New People | D42: Intro Asks | E42: Floor Walks | F42: Quote F-Ups | G42: Seed Touches | I42: Nov 23 - 27
B43: 46349 | I43: New People | J43: =IFERROR(IF(C49=0, "", C49), "")
B44: =B43+1 -> 46350 | I44: Intro Asks | J44: =IFERROR(IF(D49=0, "", D49), "")
B45: =B44+1 -> 46351 | I45: Floor Walks | J45: =IFERROR(IF(E49=0, "", E49), "")
B46: =B45+1 -> 46352 | I46: Quote F-Ups | J46: =IFERROR(IF(F49=0, "", F49), "")
B47: =B46+1 -> 46353 | I47: Seed Touches | J47: =IFERROR(IF(G49=0, "", G49), "")
I48: Goals Hit (of 5) | J48: =IF(COUNT(C40:G40)=0, "", (SUM(C43:C47)>=C40)+(SUM(D43:D47)>=D40)+(SUM(E43:E47)>=E40)+(SUM(F43:F47)>=F40)+(SUM(G43:G47)>=G40)) -> 0
...

Sheet Dec
B2: 46357
B4: Weekly Goals: | C4: 3 | D4: 1 | E4: 1 | F4: 5 | G4: 2
B5: To Go: | C5: =IF(C4="", "", C4-SUM(C7:C11)) -> 3 | D5: =IF(D4="", "", D4-SUM(D7:D11)) -> 1 | E5: =IF(E4="", "", E4-SUM(E7:E11)) -> 1 | F5: =IF(F4="", "", F4-SUM(F7:F11)) -> 5 | G5: =IF(G4="", "", G4-SUM(G7:G11)) -> 2 | L5: December Totals
C6: New People | D6: Intro Asks | E6: Floor Walks | F6: Quote F-Ups | G6: Seed Touches | I6: Nov 30 - Dec 4 | L6: New People | M6: =SUM(J7,J19,J31,J43,J55) -> 0
B7: 46356 | I7: New People | J7: =IFERROR(IF(C13=0, "", C13), "") | L7: Intro Asks | M7: =SUM(J8,J20,J32,J44,J56) -> 0
B8: =B7+1 -> 46357 | I8: Intro Asks | J8: =IFERROR(IF(D13=0, "", D13), "") | L8: Floor Walks | M8: =SUM(J9,J21,J33,J45,J57) -> 0
B9: =B8+1 -> 46358 | I9: Floor Walks | J9: =IFERROR(IF(E13=0, "", E13), "") | L9: Quote F-Ups | M9: =SUM(J10,J22,J34,J46,J58) -> 0
B10: =B9+1 -> 46359 | I10: Quote F-Ups | J10: =IFERROR(IF(F13=0, "", F13), "") | L10: Seed Touches | M10: =SUM(J11,J23,J35,J47,J59) -> 0
B11: =B10+1 -> 46360 | I11: Seed Touches | J11: =IFERROR(IF(G13=0, "", G13), "")
I12: Goals Hit (of 5) | J12: =IF(COUNT(C4:G4)=0, "", (SUM(C7:C11)>=C4)+(SUM(D7:D11)>=D4)+(SUM(E7:E11)>=E4)+(SUM(F7:F11)>=F4)+(SUM(G7:G11)>=G4)) -> 0 | L12: Perfect Weeks (5 of 5)
B13: Total: | C13: =IFERROR(IF(SUM(C7:C11)=0, "", SUM(C7:C11)), "") | D13: =IFERROR(IF(SUM(D7:D11)=0, "", SUM(D7:D11)), "") | E13: =IFERROR(IF(SUM(E7:E11)=0, "", SUM(E7:E11)), "") | F13: =IFERROR(IF(SUM(F7:F11)=0, "", SUM(F7:F11)), "") | G13: =IFERROR(IF(SUM(G7:G11)=0, "", SUM(G7:G11)), "") | L13: =(J12=5)+(J24=5)+(J36=5)+(J48=5)+(J60=5) -> 0
B16: Weekly Goals: | C16: 3 | D16: 1 | E16: 1 | F16: 5 | G16: 2
B17: To Go: | C17: =IF(C16="", "", C16-SUM(C19:C23)) -> 3 | D17: =IF(D16="", "", D16-SUM(D19:D23)) -> 1 | E17: =IF(E16="", "", E16-SUM(E19:E23)) -> 1 | F17: =IF(F16="", "", F16-SUM(F19:F23)) -> 5 | G17: =IF(G16="", "", G16-SUM(G19:G23)) -> 2
C18: New People | D18: Intro Asks | E18: Floor Walks | F18: Quote F-Ups | G18: Seed Touches | I18: Dec 7 - 11
B19: 46363 | I19: New People | J19: =IFERROR(IF(C25=0, "", C25), "")
B20: =B19+1 -> 46364 | I20: Intro Asks | J20: =IFERROR(IF(D25=0, "", D25), "")
B21: =B20+1 -> 46365 | I21: Floor Walks | J21: =IFERROR(IF(E25=0, "", E25), "")
B22: =B21+1 -> 46366 | I22: Quote F-Ups | J22: =IFERROR(IF(F25=0, "", F25), "")
B23: =B22+1 -> 46367 | I23: Seed Touches | J23: =IFERROR(IF(G25=0, "", G25), "")
I24: Goals Hit (of 5) | J24: =IF(COUNT(C16:G16)=0, "", (SUM(C19:C23)>=C16)+(SUM(D19:D23)>=D16)+(SUM(E19:E23)>=E16)+(SUM(F19:F23)>=F16)+(SUM(G19:G23)>=G16)) -> 0
B25: Total: | C25: =IFERROR(IF(SUM(C19:C23)=0, "", SUM(C19:C23)), "") | D25: =IFERROR(IF(SUM(D19:D23)=0, "", SUM(D19:D23)), "") | E25: =IFERROR(IF(SUM(E19:E23)=0, "", SUM(E19:E23)), "") | F25: =IFERROR(IF(SUM(F19:F23)=0, "", SUM(F19:F23)), "") | G25: =IFERROR(IF(SUM(G19:G23)=0, "", SUM(G19:G23)), "")
B28: Weekly Goals: | C28: 3 | D28: 1 | E28: 1 | F28: 5 | G28: 2
B29: To Go: | C29: =IF(C28="", "", C28-SUM(C31:C35)) -> 3 | D29: =IF(D28="", "", D28-SUM(D31:D35)) -> 1 | E29: =IF(E28="", "", E28-SUM(E31:E35)) -> 1 | F29: =IF(F28="", "", F28-SUM(F31:F35)) -> 5 | G29: =IF(G28="", "", G28-SUM(G31:G35)) -> 2
C30: New People | D30: Intro Asks | E30: Floor Walks | F30: Quote F-Ups | G30: Seed Touches | I30: Dec 14 - 18
B31: 46370 | I31: New People | J31: =IFERROR(IF(C37=0, "", C37), "")
B32: =B31+1 -> 46371 | I32: Intro Asks | J32: =IFERROR(IF(D37=0, "", D37), "")
B33: =B32+1 -> 46372 | I33: Floor Walks | J33: =IFERROR(IF(E37=0, "", E37), "")
B34: =B33+1 -> 46373 | I34: Quote F-Ups | J34: =IFERROR(IF(F37=0, "", F37), "")
B35: =B34+1 -> 46374 | I35: Seed Touches | J35: =IFERROR(IF(G37=0, "", G37), "")
I36: Goals Hit (of 5) | J36: =IF(COUNT(C28:G28)=0, "", (SUM(C31:C35)>=C28)+(SUM(D31:D35)>=D28)+(SUM(E31:E35)>=E28)+(SUM(F31:F35)>=F28)+(SUM(G31:G35)>=G28)) -> 0
B37: Total: | C37: =IFERROR(IF(SUM(C31:C35)=0, "", SUM(C31:C35)), "") | D37: =IFERROR(IF(SUM(D31:D35)=0, "", SUM(D31:D35)), "") | E37: =IFERROR(IF(SUM(E31:E35)=0, "", SUM(E31:E35)), "") | F37: =IFERROR(IF(SUM(F31:F35)=0, "", SUM(F31:F35)), "") | G37: =IFERROR(IF(SUM(G31:G35)=0, "", SUM(G31:G35)), "")
B40: Weekly Goals: | C40: 3 | D40: 1 | E40: 1 | F40: 5 | G40: 2
B41: To Go: | C41: =IF(C40="", "", C40-SUM(C43:C47)) -> 3 | D41: =IF(D40="", "", D40-SUM(D43:D47)) -> 1 | E41: =IF(E40="", "", E40-SUM(E43:E47)) -> 1 | F41: =IF(F40="", "", F40-SUM(F43:F47)) -> 5 | G41: =IF(G40="", "", G40-SUM(G43:G47)) -> 2
C42: New People | D42: Intro Asks | E42: Floor Walks | F42: Quote F-Ups | G42: Seed Touches | I42: Dec 21 - 25
B43: 46377 | I43: New People | J43: =IFERROR(IF(C49=0, "", C49), "")
B44: =B43+1 -> 46378 | I44: Intro Asks | J44: =IFERROR(IF(D49=0, "", D49), "")
B45: =B44+1 -> 46379 | I45: Floor Walks | J45: =IFERROR(IF(E49=0, "", E49), "")
B46: =B45+1 -> 46380 | I46: Quote F-Ups | J46: =IFERROR(IF(F49=0, "", F49), "")
B47: =B46+1 -> 46381 | I47: Seed Touches | J47: =IFERROR(IF(G49=0, "", G49), "")
I48: Goals Hit (of 5) | J48: =IF(COUNT(C40:G40)=0, "", (SUM(C43:C47)>=C40)+(SUM(D43:D47)>=D40)+(SUM(E43:E47)>=E40)+(SUM(F43:F47)>=F40)+(SUM(G43:G47)>=G40)) -> 0
...
